Workbook

Sheet Read me
B2: SOLVERAH - Company Scoring Workbook
B4: Companion to Solverah_Company_Rating_Rubric.docx. The rubric tells you HOW to pick a number; this workbook is where the numbers go. Every field maps 1:1 to the database, so what you fill in loads straight into the model.
B6: The scale (do not reinterpret)
B7: 0.0 = the LOW pole, 1.0 = the HIGH pole - identical to the candidate assessment. The model computes gap = person - company on the same axis, so flipping a pole silently inverts every gap on that dimension.
B9: How to fill it in
B10: 1. Companies tab - add one row per company: stage/size, headcount, comp posture, industry (the confounders), dated. Row 3 is a filled-in EXAMPLE; overwrite it or delete it.
B11: 2. Scores tab - 12 rows per company (6 dimensions x 2 raters). Enter score, confidence, and a one-line evidence note for each. The example company is fully scored to show the format; copy the block and change the name.
B12: 3. Two raters, blind. Rater A and Rater B score the same company from the same evidence WITHOUT seeing each other's numbers. This is the whole point - one rater can't be validated.
B13: 4. Agreement tab - updates automatically. It flags any dimension where the two raters differ by more than 0.15. A flag means the rubric anchor is ambiguous: fix the wording, don't split the difference.
B15: Legend
B16: Yellow cells = you type here. Grey cells = computed, leave alone. Green row = example, replace it.
B17: Field meanings (match the DB)
... B24: comp_vs_market - Pay POSTURE, not dollars. 1 well below - 2 below - 3 at market - 4 above - 5 well above, vs. talent-market peers (same industry/stage/geo) for COMPARABLE roles. Dollars aren't a company-level property; posture is.

Sheet Companies
A1: Companies (roster + confounders)
A2: One row per company. Confounders are common causes of culture - record them raw; the model standardizes.
A4: company_id | B4: name | C4: domain | D4: stage_index | E4: headcount | F4: comp_vs_market | G4: industry | H4: source | I4: confidence | J4: is_ground_truth | K4: as_of
A5: C001 | B5: Acme Robotics (EXAMPLE) | C5: acme.ai | D5: 2 | E5: 65 | F5: 4 | G5: tech | H5: researched | I5: 0.8 | J5: TRUE | K5: 2026-07-23

Sheet Scores
A1: Scores (long format - 6 dimensions x 2 raters per company)
A2: Enter score, confidence, and a one-line evidence note per row. Poles shown for reference; 0 = low pole, 1 = high pole.
A4: company_name | B4: dimension | C4: pole reference | D4: rater | E4: score | F4: confidence | G4: evidence_note
A5: Acme Robotics (EXAMPLE) | B5: autonomy | C5: 0 = Directed -> 1 = Self-directed | D5: A | E5: 0.75 | F5: 0.8 | G5: Postings say 'own your domain'; reviews praise low oversight.
A6: Acme Robotics (EXAMPLE) | B6: autonomy | C6: 0 = Directed -> 1 = Self-directed | D6: B | E6: 0.7 | F6: 0.7 | G6: Ownership language strong; a few mentions of founder sign-off.
A7: Acme Robotics (EXAMPLE) | B7: pace | C7: 0 = Steady -> 1 = Fast | D7: A | E7: 0.85 | F7: 0.9 | G7: Weekly ships; multiple reviews cite long hours, hypergrowth.
A8: Acme Robotics (EXAMPLE) | B8: pace | C8: 0 = Steady -> 1 = Fast | D8: B | E8: 0.8 | F8: 0.8 | G8: Clearly fast; some reviews note it's stabilizing post-Series-B.
A9: Acme Robotics (EXAMPLE) | B9: collaboration | C9: 0 = Solo -> 1 = Collective | D9: A | E9: 0.6 | F9: 0.6 | G9: Cross-functional pods, but ICs own areas end-to-end.
A10: Acme Robotics (EXAMPLE) | B10: collaboration | C10: 0 = Solo -> 1 = Collective | D10: B | E10: 0.55 | F10: 0.5 | G10: Mixed signals; standups daily, deep work protected.
A11: Acme Robotics (EXAMPLE) | B11: feedback | C11: 0 = Sparse/gentle -> 1 = Frequent/blunt | D11: A | E11: 0.7 | F11: 0.7 | G11: 'Direct communication' a stated value; blunt-but-kind reviews.
A12: Acme Robotics (EXAMPLE) | B12: feedback | C12: 0 = Sparse/gentle -> 1 = Frequent/blunt | D12: B | E12: 0.65 | F12: 0.6 | G12: Fairly direct; not radical-candor level.
A13: Acme Robotics (EXAMPLE) | B13: innovation | C13: 0 = Execute/optimize -> 1 = Invent/explore | D13: A | E13: 0.8 | F13: 0.8 | G13: 0-to-1 robotics R&D; patents; explicit failed-bet tolerance.
A14: Acme Robotics (EXAMPLE) | B14: innovation | C14: 0 = Execute/optimize -> 1 = Invent/explore | D14: B | E14: 0.85 | F14: 0.8 | G14: Core work is inventing new capability, not optimizing.
A15: Acme Robotics (EXAMPLE) | B15: decision | C15: 0 = Intuition/judgement -> 1 = Data/analysis | D15: A | E15: 0.45 | F15: 0.5 | G15: Founder-vision led; data used to confirm, not decide.
A16: Acme Robotics (EXAMPLE) | B16: decision | C16: 0 = Intuition/judgement -> 1 = Data/analysis | D16: B | E16: 0.4 | F16: 0.5 | G16: Leans intuition; analytics team small.
B17: autonomy | C17: 0 = Directed -> 1 = Self-directed | D17: A
B18: autonomy | C18: 0 = Directed -> 1 = Self-directed | D18: B
B19: pace | C19: 0 = Steady -> 1 = Fast | D19: A
B20: pace | C20: 0 = Steady -> 1 = Fast | D20: B
B21: collaboration | C21: 0 = Solo -> 1 = Collective | D21: A
B22: collaboration | C22: 0 = Solo -> 1 = Collective | D22: B
B23: feedback | C23: 0 = Sparse/gentle -> 1 = Frequent/blunt | D23: A
B24: feedback | C24: 0 = Sparse/gentle -> 1 = Frequent/blunt | D24: B
B25: innovation | C25: 0 = Execute/optimize -> 1 = Invent/explore | D25: A
B26: innovation | C26: 0 = Execute/optimize -> 1 = Invent/explore | D26: B
B27: decision | C27: 0 = Intuition/judgement -> 1 = Data/analysis | D27: A
B28: decision | C28: 0 = Intuition/judgement -> 1 = Data/analysis | D28: B
... B256: decision | C256: 0 = Intuition/judgement -> 1 = Data/analysis | D256: B

Sheet Agreement
A1: Inter-rater agreement (auto-computed)
A2: Pulls both raters' scores per company x dimension. Flags gaps > 0.15 - those anchors need rewording, not averaging.
A4: Mean gap (scored pairs): | C4: =IFERROR(AVERAGE(E8:E127),"-")
A5: Dimensions flagged (>0.15): | C5: =COUNTIF(F8:F127,"REVIEW")
A7: company | B7: dimension | C7: rater A | D7: rater B | E7: gap | F7: flag
A8: =IF(Companies!$B$5="","",Companies!$B$5) | B8: autonomy | C8: =IF(OR(Companies!$B$5="",COUNTIFS(Scores!$A$5:$A$256,Companies!$B$5,Scores!$B$5:$B$256,"autonomy",Scores!$D$5:$D$256,"A")=0),"",SUMIFS(Scores!$E$5:$E$256,Scores!$A$5:$A$256,Companies!$B$5,Scores!$B$5:$B$256,"autonomy",Scores!$D$5:$D$256,"A")) | D8: =IF(OR(Companies!$B$5="",COUNTIFS(Scores!$A$5:$A$256,Companies!$B$5,Scores!$B$5:$B$256,"autonomy",Scores!$D$5:$D$256,"B")=0),"",SUMIFS(Scores!$E$5:$E$256,Scores!$A$5:$A$256,Companies!$B$5,Scores!$B$5:$B$256,"autonomy",Scores!$D$5:$D$256,"B")) | E8: =IF(OR(C8="",D8=""),"",ABS(C8-D8)) | F8: =IF(E8="","",IF(E8>0.15,"REVIEW",""))
A9: =IF(Companies!$B$5="","",Companies!$B$5) | B9: pace | C9: =IF(OR(Companies!$B$5="",COUNTIFS(Scores!$A$5:$A$256,Companies!$B$5,Scores!$B$5:$B$256,"pace",Scores!$D$5:$D$256,"A")=0),"",SUMIFS(Scores!$E$5:$E$256,Scores!$A$5:$A$256,Companies!$B$5,Scores!$B$5:$B$256,"pace",Scores!$D$5:$D$256,"A")) | D9: =IF(OR(Companies!$B$5="",COUNTIFS(Scores!$A$5:$A$256,Companies!$B$5,Scores!$B$5:$B$256,"pace",Scores!$D$5:$D$256,"B")=0),"",SUMIFS(Scores!$E$5:$E$256,Scores!$A$5:$A$256,Companies!$B$5,Scores!$B$5:$B$256,"pace",Scores!$D$5:$D$256,"B")) | E9: =IF(OR(C9="",D9=""),"",ABS(C9-D9)) | F9: =IF(E9="","",IF(E9>0.15,"REVIEW",""))
A10: =IF(Companies!$B$5="","",Companies!$B$5) | B10: collaboration | C10: =IF(OR(Companies!$B$5="",COUNTIFS(Scores!$A$5:$A$256,Companies!$B$5,Scores!$B$5:$B$256,"collaboration",Scores!$D$5:$D$256,"A")=0),"",SUMIFS(Scores!$E$5:$E$256,Scores!$A$5:$A$256,Companies!$B$5,Scores!$B$5:$B$256,"collaboration",Scores!$D$5:$D$256,"A")) | D10: =IF(OR(Companies!$B$5="",COUNTIFS(Scores!$A$5:$A$256,Companies!$B$5,Scores!$B$5:$B$256,"collaboration",Scores!$D$5:$D$256,"B")=0),"",SUMIFS(Scores!$E$5:$E$256,Scores!$A$5:$A$256,Companies!$B$5,Scores!$B$5:$B$256,"collaboration",Scores!$D$5:$D$256,"B")) | E10: =IF(OR(C10="",D10=""),"",ABS(C10-D10)) | F10: =IF(E10="","",IF(E10>0.15,"REVIEW",""))
A11: =IF(Companies!$B$5="","",Companies!$B$5) | B11: feedback | C11: =IF(OR(Companies!$B$5="",COUNTIFS(Scores!$A$5:$A$256,Companies!$B$5,Scores!$B$5:$B$256,"feedback",Scores!$D$5:$D$256,"A")=0),"",SUMIFS(Scores!$E$5:$E$256,Scores!$A$5:$A$256,Companies!$B$5,Scores!$B$5:$B$256,"feedback",Scores!$D$5:$D$256,"A")) | D11: =IF(OR(Companies!$B$5="",COUNTIFS(Scores!$A$5:$A$256,Companies!$B$5,Scores!$B$5:$B$256,"feedback",Scores!$D$5:$D$256,"B")=0),"",SUMIFS(Scores!$E$5:$E$256,Scores!$A$5:$A$256,Companies!$B$5,Scores!$B$5:$B$256,"feedback",Scores!$D$5:$D$256,"B")) | E11: =IF(OR(C11="",D11=""),"",ABS(C11-D11)) | F11: =IF(E11="","",IF(E11>0.15,"REVIEW",""))
A12: =IF(Companies!$B$5="","",Companies!$B$5) | B12: innovation | C12: =IF(OR(Companies!$B$5="",COUNTIFS(Scores!$A$5:$A$256,Companies!$B$5,Scores!$B$5:$B$256,"innovation",Scores!$D$5:$D$256,"A")=0),"",SUMIFS(Scores!$E$5:$E$256,Scores!$A$5:$A$256,Companies!$B$5,Scores!$B$5:$B$256,"innovation",Scores!$D$5:$D$256,"A")) | D12: =IF(OR(Companies!$B$5="",COUNTIFS(Scores!$A$5:$A$256,Companies!$B$5,Scores!$B$5:$B$256,"innovation",Scores!$D$5:$D$256,"B")=0),"",SUMIFS(Scores!$E$5:$E$256,Scores!$A$5:$A$256,Companies!$B$5,Scores!$B$5:$B$256,"innovation",Scores!$D$5:$D$256,"B")) | E12: =IF(OR(C12="",D12=""),"",ABS(C12-D12)) | F12: =IF(E12="","",IF(E12>0.15,"REVIEW",""))
A13: =IF(Companies!$B$5="","",Companies!$B$5) | B13: decision | C13: =IF(OR(Companies!$B$5="",COUNTIFS(Scores!$A$5:$A$256,Companies!$B$5,Scores!$B$5:$B$256,"decision",Scores!$D$5:$D$256,"A")=0),"",SUMIFS(Scores!$E$5:$E$256,Scores!$A$5:$A$256,Companies!$B$5,Scores!$B$5:$B$256,"decision",Scores!$D$5:$D$256,"A")) | D13: =IF(OR(Companies!$B$5="",COUNTIFS(Scores!$A$5:$A$256,Companies!$B$5,Scores!$B$5:$B$256,"decision",Scores!$D$5:$D$256,"B")=0),"",SUMIFS(Scores!$E$5:$E$256,Scores!$A$5:$A$256,Companies!$B$5,Scores!$B$5:$B$256,"decision",Scores!$D$5:$D$256,"B")) | E13: =IF(OR(C13="",D13=""),"",ABS(C13-D13)) | F13: =IF(E13="","",IF(E13>0.15,"REVIEW",""))
A14: =IF(Companies!$B$6="","",Companies!$B$6) | B14: autonomy | C14: =IF(OR(Companies!$B$6="",COUNTIFS(Scores!$A$5:$A$256,Companies!$B$6,Scores!$B$5:$B$256,"autonomy",Scores!$D$5:$D$256,"A")=0),"",SUMIFS(Scores!$E$5:$E$256,Scores!$A$5:$A$256,Companies!$B$6,Scores!$B$5:$B$256,"autonomy",Scores!$D$5:$D$256,"A")) | D14: =IF(OR(Companies!$B$6="",COUNTIFS(Scores!$A$5:$A$256,Companies!$B$6,Scores!$B$5:$B$256,"autonomy",Scores!$D$5:$D$256,"B")=0),"",SUMIFS(Scores!$E$5:$E$256,Scores!$A$5:$A$256,Companies!$B$6,Scores!$B$5:$B$256,"autonomy",Scores!$D$5:$D$256,"B")) | E14: =IF(OR(C14="",D14=""),"",ABS(C14-D14)) | F14: =IF(E14="","",IF(E14>0.15,"REVIEW",""))
A15: =IF(Companies!$B$6="","",Companies!$B$6) | B15: pace | C15: =IF(OR(Companies!$B$6="",COUNTIFS(Scores!$A$5:$A$256,Companies!$B$6,Scores!$B$5:$B$256,"pace",Scores!$D$5:$D$256,"A")=0),"",SUMIFS(Scores!$E$5:$E$256,Scores!$A$5:$A$256,Companies!$B$6,Scores!$B$5:$B$256,"pace",Scores!$D$5:$D$256,"A")) | D15: =IF(OR(Companies!$B$6="",COUNTIFS(Scores!$A$5:$A$256,Companies!$B$6,Scores!$B$5:$B$256,"pace",Scores!$D$5:$D$256,"B")=0),"",SUMIFS(Scores!$E$5:$E$256,Scores!$A$5:$A$256,Companies!$B$6,Scores!$B$5:$B$256,"pace",Scores!$D$5:$D$256,"B")) | E15: =IF(OR(C15="",D15=""),"",ABS(C15-D15)) | F15: =IF(E15="","",IF(E15>0.15,"REVIEW",""))
A16: =IF(Companies!$B$6="","",Companies!$B$6) | B16: collaboration | C16: =IF(OR(Companies!$B$6="",COUNTIFS(Scores!$A$5:$A$256,Companies!$B$6,Scores!$B$5:$B$256,"collaboration",Scores!$D$5:$D$256,"A")=0),"",SUMIFS(Scores!$E$5:$E$256,Scores!$A$5:$A$256,Companies!$B$6,Scores!$B$5:$B$256,"collaboration",Scores!$D$5:$D$256,"A")) | D16: =IF(OR(Companies!$B$6="",COUNTIFS(Scores!$A$5:$A$256,Companies!$B$6,Scores!$B$5:$B$256,"collaboration",Scores!$D$5:$D$256,"B")=0),"",SUMIFS(Scores!$E$5:$E$256,Scores!$A$5:$A$256,Companies!$B$6,Scores!$B$5:$B$256,"collaboration",Scores!$D$5:$D$256,"B")) | E16: =IF(OR(C16="",D16=""),"",ABS(C16-D16)) | F16: =IF(E16="","",IF(E16>0.15,"REVIEW",""))
A17: =IF(Companies!$B$6="","",Companies!$B$6) | B17: feedback | C17: =IF(OR(Companies!$B$6="",COUNTIFS(Scores!$A$5:$A$256,Companies!$B$6,Scores!$B$5:$B$256,"feedback",Scores!$D$5:$D$256,"A")=0),"",SUMIFS(Scores!$E$5:$E$256,Scores!$A$5:$A$256,Companies!$B$6,Scores!$B$5:$B$256,"feedback",Scores!$D$5:$D$256,"A")) | D17: =IF(OR(Companies!$B$6="",COUNTIFS(Scores!$A$5:$A$256,Companies!$B$6,Scores!$B$5:$B$256,"feedback",Scores!$D$5:$D$256,"B")=0),"",SUMIFS(Scores!$E$5:$E$256,Scores!$A$5:$A$256,Companies!$B$6,Scores!$B$5:$B$256,"feedback",Scores!$D$5:$D$256,"B")) | E17: =IF(OR(C17="",D17=""),"",ABS(C17-D17)) | F17: =IF(E17="","",IF(E17>0.15,"REVIEW",""))
A18: =IF(Companies!$B$6="","",Companies!$B$6) | B18: innovation | C18: =IF(OR(Companies!$B$6="",COUNTIFS(Scores!$A$5:$A$256,Companies!$B$6,Scores!$B$5:$B$256,"innovation",Scores!$D$5:$D$256,"A")=0),"",SUMIFS(Scores!$E$5:$E$256,Scores!$A$5:$A$256,Companies!$B$6,Scores!$B$5:$B$256,"innovation",Scores!$D$5:$D$256,"A")) | D18: =IF(OR(Companies!$B$6="",COUNTIFS(Scores!$A$5:$A$256,Companies!$B$6,Scores!$B$5:$B$256,"innovation",Scores!$D$5:$D$256,"B")=0),"",SUMIFS(Scores!$E$5:$E$256,Scores!$A$5:$A$256,Companies!$B$6,Scores!$B$5:$B$256,"innovation",Scores!$D$5:$D$256,"B")) | E18: =IF(OR(C18="",D18=""),"",ABS(C18-D18)) | F18: =IF(E18="","",IF(E18>0.15,"REVIEW",""))
A19: =IF(Companies!$B$6="","",Companies!$B$6) | B19: decision | C19: =IF(OR(Companies!$B$6="",COUNTIFS(Scores!$A$5:$A$256,Companies!$B$6,Scores!$B$5:$B$256,"decision",Scores!$D$5:$D$256,"A")=0),"",SUMIFS(Scores!$E$5:$E$256,Scores!$A$5:$A$256,Companies!$B$6,Scores!$B$5:$B$256,"decision",Scores!$D$5:$D$256,"A")) | D19: =IF(OR(Companies!$B$6="",COUNTIFS(Scores!$A$5:$A$256,Companies!$B$6,Scores!$B$5:$B$256,"decision",Scores!$D$5:$D$256,"B")=0),"",SUMIFS(Scores!$E$5:$E$256,Scores!$A$5:$A$256,Companies!$B$6,Scores!$B$5:$B$256,"decision",Scores!$D$5:$D$256,"B")) | E19: =IF(OR(C19="",D19=""),"",ABS(C19-D19)) | F19: =IF(E19="","",IF(E19>0.15,"REVIEW",""))
A20: =IF(Companies!$B$7="","",Companies!$B$7) | B20: autonomy | C20: =IF(OR(Companies!$B$7="",COUNTIFS(Scores!$A$5:$A$256,Companies!$B$7,Scores!$B$5:$B$256,"autonomy",Scores!$D$5:$D$256,"A")=0),"",SUMIFS(Scores!$E$5:$E$256,Scores!$A$5:$A$256,Companies!$B$7,Scores!$B$5:$B$256,"autonomy",Scores!$D$5:$D$256,"A")) | D20: =IF(OR(Companies!$B$7="",COUNTIFS(Scores!$A$5:$A$256,Companies!$B$7,Scores!$B$5:$B$256,"autonomy",Scores!$D$5:$D$256,"B")=0),"",SUMIFS(Scores!$E$5:$E$256,Scores!$A$5:$A$256,Companies!$B$7,Scores!$B$5:$B$256,"autonomy",Scores!$D$5:$D$256,"B")) | E20: =IF(OR(C20="",D20=""),"",ABS(C20-D20)) | F20: =IF(E20="","",IF(E20>0.15,"REVIEW",""))
A21: =IF(Companies!$B$7="","",Companies!$B$7) | B21: pace | C21: =IF(OR(Companies!$B$7="",COUNTIFS(Scores!$A$5:$A$256,Companies!$B$7,Scores!$B$5:$B$256,"pace",Scores!$D$5:$D$256,"A")=0),"",SUMIFS(Scores!$E$5:$E$256,Scores!$A$5:$A$256,Companies!$B$7,Scores!$B$5:$B$256,"pace",Scores!$D$5:$D$256,"A")) | D21: =IF(OR(Companies!$B$7="",COUNTIFS(Scores!$A$5:$A$256,Companies!$B$7,Scores!$B$5:$B$256,"pace",Scores!$D$5:$D$256,"B")=0),"",SUMIFS(Scores!$E$5:$E$256,Scores!$A$5:$A$256,Companies!$B$7,Scores!$B$5:$B$256,"pace",Scores!$D$5:$D$256,"B")) | E21: =IF(OR(C21="",D21=""),"",ABS(C21-D21)) | F21: =IF(E21="","",IF(E21>0.15,"REVIEW",""))
A22: =IF(Companies!$B$7="","",Companies!$B$7) | B22: collaboration | C22: =IF(OR(Companies!$B$7="",COUNTIFS(Scores!$A$5:$A$256,Companies!$B$7,Scores!$B$5:$B$256,"collaboration",Scores!$D$5:$D$256,"A")=0),"",SUMIFS(Scores!$E$5:$E$256,Scores!$A$5:$A$256,Companies!$B$7,Scores!$B$5:$B$256,"collaboration",Scores!$D$5:$D$256,"A")) | D22: =IF(OR(Companies!$B$7="",COUNTIFS(Scores!$A$5:$A$256,Companies!$B$7,Scores!$B$5:$B$256,"collaboration",Scores!$D$5:$D$256,"B")=0),"",SUMIFS(Scores!$E$5:$E$256,Scores!$A$5:$A$256,Companies!$B$7,Scores!$B$5:$B$256,"collaboration",Scores!$D$5:$D$256,"B")) | E22: =IF(OR(C22="",D22=""),"",ABS(C22-D22)) | F22: =IF(E22="","",IF(E22>0.15,"REVIEW",""))
A23: =IF(Companies!$B$7="","",Companies!$B$7) | B23: feedback | C23: =IF(OR(Companies!$B$7="",COUNTIFS(Scores!$A$5:$A$256,Companies!$B$7,Scores!$B$5:$B$256,"feedback",Scores!$D$5:$D$256,"A")=0),"",SUMIFS(Scores!$E$5:$E$256,Scores!$A$5:$A$256,Companies!$B$7,Scores!$B$5:$B$256,"feedback",Scores!$D$5:$D$256,"A")) | D23: =IF(OR(Companies!$B$7="",COUNTIFS(Scores!$A$5:$A$256,Companies!$B$7,Scores!$B$5:$B$256,"feedback",Scores!$D$5:$D$256,"B")=0),"",SUMIFS(Scores!$E$5:$E$256,Scores!$A$5:$A$256,Companies!$B$7,Scores!$B$5:$B$256,"feedback",Scores!$D$5:$D$256,"B")) | E23: =IF(OR(C23="",D23=""),"",ABS(C23-D23)) | F23: =IF(E23="","",IF(E23>0.15,"REVIEW",""))
A24: =IF(Companies!$B$7="","",Companies!$B$7) | B24: innovation | C24: =IF(OR(Companies!$B$7="",COUNTIFS(Scores!$A$5:$A$256,Companies!$B$7,Scores!$B$5:$B$256,"innovation",Scores!$D$5:$D$256,"A")=0),"",SUMIFS(Scores!$E$5:$E$256,Scores!$A$5:$A$256,Companies!$B$7,Scores!$B$5:$B$256,"innovation",Scores!$D$5:$D$256,"A")) | D24: =IF(OR(Companies!$B$7="",COUNTIFS(Scores!$A$5:$A$256,Companies!$B$7,Scores!$B$5:$B$256,"innovation",Scores!$D$5:$D$256,"B")=0),"",SUMIFS(Scores!$E$5:$E$256,Scores!$A$5:$A$256,Companies!$B$7,Scores!$B$5:$B$256,"innovation",Scores!$D$5:$D$256,"B")) | E24: =IF(OR(C24="",D24=""),"",ABS(C24-D24)) | F24: =IF(E24="","",IF(E24>0.15,"REVIEW",""))
A25: =IF(Companies!$B$7="","",Companies!$B$7) | B25: decision | C25: =IF(OR(Companies!$B$7="",COUNTIFS(Scores!$A$5:$A$256,Companies!$B$7,Scores!$B$5:$B$256,"decision",Scores!$D$5:$D$256,"A")=0),"",SUMIFS(Scores!$E$5:$E$256,Scores!$A$5:$A$256,Companies!$B$7,Scores!$B$5:$B$256,"decision",Scores!$D$5:$D$256,"A")) | D25: =IF(OR(Companies!$B$7="",COUNTIFS(Scores!$A$5:$A$256,Companies!$B$7,Scores!$B$5:$B$256,"decision",Scores!$D$5:$D$256,"B")=0),"",SUMIFS(Scores!$E$5:$E$256,Scores!$A$5:$A$256,Companies!$B$7,Scores!$B$5:$B$256,"decision",Scores!$D$5:$D$256,"B")) | E25: =IF(OR(C25="",D25=""),"",ABS(C25-D25)) | F25: =IF(E25="","",IF(E25>0.15,"REVIEW",""))
A26: =IF(Companies!$B$8="","",Companies!$B$8) | B26: autonomy | C26: =IF(OR(Companies!$B$8="",COUNTIFS(Scores!$A$5:$A$256,Companies!$B$8,Scores!$B$5:$B$256,"autonomy",Scores!$D$5:$D$256,"A")=0),"",SUMIFS(Scores!$E$5:$E$256,Scores!$A$5:$A$256,Companies!$B$8,Scores!$B$5:$B$256,"autonomy",Scores!$D$5:$D$256,"A")) | D26: =IF(OR(Companies!$B$8="",COUNTIFS(Scores!$A$5:$A$256,Companies!$B$8,Scores!$B$5:$B$256,"autonomy",Scores!$D$5:$D$256,"B")=0),"",SUMIFS(Scores!$E$5:$E$256,Scores!$A$5:$A$256,Companies!$B$8,Scores!$B$5:$B$256,"autonomy",Scores!$D$5:$D$256,"B")) | E26: =IF(OR(C26="",D26=""),"",ABS(C26-D26)) | F26: =IF(E26="","",IF(E26>0.15,"REVIEW",""))
A27: =IF(Companies!$B$8="","",Companies!$B$8) | B27: pace | C27: =IF(OR(Companies!$B$8="",COUNTIFS(Scores!$A$5:$A$256,Companies!$B$8,Scores!$B$5:$B$256,"pace",Scores!$D$5:$D$256,"A")=0),"",SUMIFS(Scores!$E$5:$E$256,Scores!$A$5:$A$256,Companies!$B$8,Scores!$B$5:$B$256,"pace",Scores!$D$5:$D$256,"A")) | D27: =IF(OR(Companies!$B$8="",COUNTIFS(Scores!$A$5:$A$256,Companies!$B$8,Scores!$B$5:$B$256,"pace",Scores!$D$5:$D$256,"B")=0),"",SUMIFS(Scores!$E$5:$E$256,Scores!$A$5:$A$256,Companies!$B$8,Scores!$B$5:$B$256,"pace",Scores!$D$5:$D$256,"B")) | E27: =IF(OR(C27="",D27=""),"",ABS(C27-D27)) | F27: =IF(E27="","",IF(E27>0.15,"REVIEW",""))
A28: =IF(Companies!$B$8="","",Companies!$B$8) | B28: collaboration | C28: =IF(OR(Companies!$B$8="",COUNTIFS(Scores!$A$5:$A$256,Companies!$B$8,Scores!$B$5:$B$256,"collaboration",Scores!$D$5:$D$256,"A")=0),"",SUMIFS(Scores!$E$5:$E$256,Scores!$A$5:$A$256,Companies!$B$8,Scores!$B$5:$B$256,"collaboration",Scores!$D$5:$D$256,"A")) | D28: =IF(OR(Companies!$B$8="",COUNTIFS(Scores!$A$5:$A$256,Companies!$B$8,Scores!$B$5:$B$256,"collaboration",Scores!$D$5:$D$256,"B")=0),"",SUMIFS(Scores!$E$5:$E$256,Scores!$A$5:$A$256,Companies!$B$8,Scores!$B$5:$B$256,"collaboration",Scores!$D$5:$D$256,"B")) | E28: =IF(OR(C28="",D28=""),"",ABS(C28-D28)) | F28: =IF(E28="","",IF(E28>0.15,"REVIEW",""))
A29: =IF(Companies!$B$8="","",Companies!$B$8) | B29: feedback | C29: =IF(OR(Companies!$B$8="",COUNTIFS(Scores!$A$5:$A$256,Companies!$B$8,Scores!$B$5:$B$256,"feedback",Scores!$D$5:$D$256,"A")=0),"",SUMIFS(Scores!$E$5:$E$256,Scores!$A$5:$A$256,Companies!$B$8,Scores!$B$5:$B$256,"feedback",Scores!$D$5:$D$256,"A")) | D29: =IF(OR(Companies!$B$8="",COUNTIFS(Scores!$A$5:$A$256,Companies!$B$8,Scores!$B$5:$B$256,"feedback",Scores!$D$5:$D$256,"B")=0),"",SUMIFS(Scores!$E$5:$E$256,Scores!$A$5:$A$256,Companies!$B$8,Scores!$B$5:$B$256,"feedback",Scores!$D$5:$D$256,"B")) | E29: =IF(OR(C29="",D29=""),"",ABS(C29-D29)) | F29: =IF(E29="","",IF(E29>0.15,"REVIEW",""))
A30: =IF(Companies!$B$8="","",Companies!$B$8) | B30: innovation | C30: =IF(OR(Companies!$B$8="",COUNTIFS(Scores!$A$5:$A$256,Companies!$B$8,Scores!$B$5:$B$256,"innovation",Scores!$D$5:$D$256,"A")=0),"",SUMIFS(Scores!$E$5:$E$256,Scores!$A$5:$A$256,Companies!$B$8,Scores!$B$5:$B$256,"innovation",Scores!$D$5:$D$256,"A")) | D30: =IF(OR(Companies!$B$8="",COUNTIFS(Scores!$A$5:$A$256,Companies!$B$8,Scores!$B$5:$B$256,"innovation",Scores!$D$5:$D$256,"B")=0),"",SUMIFS(Scores!$E$5:$E$256,Scores!$A$5:$A$256,Companies!$B$8,Scores!$B$5:$B$256,"innovation",Scores!$D$5:$D$256,"B")) | E30: =IF(OR(C30="",D30=""),"",ABS(C30-D30)) | F30: =IF(E30="","",IF(E30>0.15,"REVIEW",""))
A31: =IF(Companies!$B$8="","",Companies!$B$8) | B31: decision | C31: =IF(OR(Companies!$B$8="",COUNTIFS(Scores!$A$5:$A$256,Companies!$B$8,Scores!$B$5:$B$256,"decision",Scores!$D$5:$D$256,"A")=0),"",SUMIFS(Scores!$E$5:$E$256,Scores!$A$5:$A$256,Companies!$B$8,Scores!$B$5:$B$256,"decision",Scores!$D$5:$D$256,"A")) | D31: =IF(OR(Companies!$B$8="",COUNTIFS(Scores!$A$5:$A$256,Companies!$B$8,Scores!$B$5:$B$256,"decision",Scores!$D$5:$D$256,"B")=0),"",SUMIFS(Scores!$E$5:$E$256,Scores!$A$5:$A$256,Companies!$B$8,Scores!$B$5:$B$256,"decision",Scores!$D$5:$D$256,"B")) | E31: =IF(OR(C31="",D31=""),"",ABS(C31-D31)) | F31: =IF(E31="","",IF(E31>0.15,"REVIEW",""))
A32: =IF(Companies!$B$9="","",Companies!$B$9) | B32: autonomy | C32: =IF(OR(Companies!$B$9="",COUNTIFS(Scores!$A$5:$A$256,Companies!$B$9,Scores!$B$5:$B$256,"autonomy",Scores!$D$5:$D$256,"A")=0),"",SUMIFS(Scores!$E$5:$E$256,Scores!$A$5:$A$256,Companies!$B$9,Scores!$B$5:$B$256,"autonomy",Scores!$D$5:$D$256,"A")) | D32: =IF(OR(Companies!$B$9="",COUNTIFS(Scores!$A$5:$A$256,Companies!$B$9,Scores!$B$5:$B$256,"autonomy",Scores!$D$5:$D$256,"B")=0),"",SUMIFS(Scores!$E$5:$E$256,Scores!$A$5:$A$256,Companies!$B$9,Scores!$B$5:$B$256,"autonomy",Scores!$D$5:$D$256,"B")) | E32: =IF(OR(C32="",D32=""),"",ABS(C32-D32)) | F32: =IF(E32="","",IF(E32>0.15,"REVIEW",""))
A33: =IF(Companies!$B$9="","",Companies!$B$9) | B33: pace | C33: =IF(OR(Companies!$B$9="",COUNTIFS(Scores!$A$5:$A$256,Companies!$B$9,Scores!$B$5:$B$256,"pace",Scores!$D$5:$D$256,"A")=0),"",SUMIFS(Scores!$E$5:$E$256,Scores!$A$5:$A$256,Companies!$B$9,Scores!$B$5:$B$256,"pace",Scores!$D$5:$D$256,"A")) | D33: =IF(OR(Companies!$B$9="",COUNTIFS(Scores!$A$5:$A$256,Companies!$B$9,Scores!$B$5:$B$256,"pace",Scores!$D$5:$D$256,"B")=0),"",SUMIFS(Scores!$E$5:$E$256,Scores!$A$5:$A$256,Companies!$B$9,Scores!$B$5:$B$256,"pace",Scores!$D$5:$D$256,"B")) | E33: =IF(OR(C33="",D33=""),"",ABS(C33-D33)) | F33: =IF(E33="","",IF(E33>0.15,"REVIEW",""))
A34: =IF(Companies!$B$9="","",Companies!$B$9) | B34: collaboration | C34: =IF(OR(Companies!$B$9="",COUNTIFS(Scores!$A$5:$A$256,Companies!$B$9,Scores!$B$5:$B$256,"collaboration",Scores!$D$5:$D$256,"A")=0),"",SUMIFS(Scores!$E$5:$E$256,Scores!$A$5:$A$256,Companies!$B$9,Scores!$B$5:$B$256,"collaboration",Scores!$D$5:$D$256,"A")) | D34: =IF(OR(Companies!$B$9="",COUNTIFS(Scores!$A$5:$A$256,Companies!$B$9,Scores!$B$5:$B$256,"collaboration",Scores!$D$5:$D$256,"B")=0),"",SUMIFS(Scores!$E$5:$E$256,Scores!$A$5:$A$256,Companies!$B$9,Scores!$B$5:$B$256,"collaboration",Scores!$D$5:$D$256,"B")) | E34: =IF(OR(C34="",D34=""),"",ABS(C34-D34)) | F34: =IF(E34="","",IF(E34>0.15,"REVIEW",""))
A35: =IF(Companies!$B$9="","",Companies!$B$9) | B35: feedback | C35: =IF(OR(Companies!$B$9="",COUNTIFS(Scores!$A$5:$A$256,Companies!$B$9,Scores!$B$5:$B$256,"feedback",Scores!$D$5:$D$256,"A")=0),"",SUMIFS(Scores!$E$5:$E$256,Scores!$A$5:$A$256,Companies!$B$9,Scores!$B$5:$B$256,"feedback",Scores!$D$5:$D$256,"A")) | D35: =IF(OR(Companies!$B$9="",COUNTIFS(Scores!$A$5:$A$256,Companies!$B$9,Scores!$B$5:$B$256,"feedback",Scores!$D$5:$D$256,"B")=0),"",SUMIFS(Scores!$E$5:$E$256,Scores!$A$5:$A$256,Companies!$B$9,Scores!$B$5:$B$256,"feedback",Scores!$D$5:$D$256,"B")) | E35: =IF(OR(C35="",D35=""),"",ABS(C35-D35)) | F35: =IF(E35="","",IF(E35>0.15,"REVIEW",""))
A36: =IF(Companies!$B$9="","",Companies!$B$9) | B36: innovation | C36: =IF(OR(Companies!$B$9="",COUNTIFS(Scores!$A$5:$A$256,Companies!$B$9,Scores!$B$5:$B$256,"innovation",Scores!$D$5:$D$256,"A")=0),"",SUMIFS(Scores!$E$5:$E$256,Scores!$A$5:$A$256,Companies!$B$9,Scores!$B$5:$B$256,"innovation",Scores!$D$5:$D$256,"A")) | D36: =IF(OR(Companies!$B$9="",COUNTIFS(Scores!$A$5:$A$256,Companies!$B$9,Scores!$B$5:$B$256,"innovation",Scores!$D$5:$D$256,"B")=0),"",SUMIFS(Scores!$E$5:$E$256,Scores!$A$5:$A$256,Companies!$B$9,Scores!$B$5:$B$256,"innovation",Scores!$D$5:$D$256,"B")) | E36: =IF(OR(C36="",D36=""),"",ABS(C36-D36)) | F36: =IF(E36="","",IF(E36>0.15,"REVIEW",""))
A37: =IF(Companies!$B$9="","",Companies!$B$9) | B37: decision | C37: =IF(OR(Companies!$B$9="",COUNTIFS(Scores!$A$5:$A$256,Companies!$B$9,Scores!$B$5:$B$256,"decision",Scores!$D$5:$D$256,"A")=0),"",SUMIFS(Scores!$E$5:$E$256,Scores!$A$5:$A$256,Companies!$B$9,Scores!$B$5:$B$256,"decision",Scores!$D$5:$D$256,"A")) | D37: =IF(OR(Companies!$B$9="",COUNTIFS(Scores!$A$5:$A$256,Companies!$B$9,Scores!$B$5:$B$256,"decision",Scores!$D$5:$D$256,"B")=0),"",SUMIFS(Scores!$E$5:$E$256,Scores!$A$5:$A$256,Companies!$B$9,Scores!$B$5:$B$256,"decision",Scores!$D$5:$D$256,"B")) | E37: =IF(OR(C37="",D37=""),"",ABS(C37-D37)) | F37: =IF(E37="","",IF(E37>0.15,"REVIEW",""))
A38: =IF(Companies!$B$10="","",Companies!$B$10) | B38: autonomy | C38: =IF(OR(Companies!$B$10="",COUNTIFS(Scores!$A$5:$A$256,Companies!$B$10,Scores!$B$5:$B$256,"autonomy",Scores!$D$5:$D$256,"A")=0),"",SUMIFS(Scores!$E$5:$E$256,Scores!$A$5:$A$256,Companies!$B$10,Scores!$B$5:$B$256,"autonomy",Scores!$D$5:$D$256,"A")) | D38: =IF(OR(Companies!$B$10="",COUNTIFS(Scores!$A$5:$A$256,Companies!$B$10,Scores!$B$5:$B$256,"autonomy",Scores!$D$5:$D$256,"B")=0),"",SUMIFS(Scores!$E$5:$E$256,Scores!$A$5:$A$256,Companies!$B$10,Scores!$B$5:$B$256,"autonomy",Scores!$D$5:$D$256,"B")) | E38: =IF(OR(C38="",D38=""),"",ABS(C38-D38)) | F38: =IF(E38="","",IF(E38>0.15,"REVIEW",""))
A39: =IF(Companies!$B$10="","",Companies!$B$10) | B39: pace | C39: =IF(OR(Companies!$B$10="",COUNTIFS(Scores!$A$5:$A$256,Companies!$B$10,Scores!$B$5:$B$256,"pace",Scores!$D$5:$D$256,"A")=0),"",SUMIFS(Scores!$E$5:$E$256,Scores!$A$5:$A$256,Companies!$B$10,Scores!$B$5:$B$256,"pace",Scores!$D$5:$D$256,"A")) | D39: =IF(OR(Companies!$B$10="",COUNTIFS(Scores!$A$5:$A$256,Companies!$B$10,Scores!$B$5:$B$256,"pace",Scores!$D$5:$D$256,"B")=0),"",SUMIFS(Scores!$E$5:$E$256,Scores!$A$5:$A$256,Companies!$B$10,Scores!$B$5:$B$256,"pace",Scores!$D$5:$D$256,"B")) | E39: =IF(OR(C39="",D39=""),"",ABS(C39-D39)) | F39: =IF(E39="","",IF(E39>0.15,"REVIEW",""))
A40: =IF(Companies!$B$10="","",Companies!$B$10) | B40: collaboration | C40: =IF(OR(Companies!$B$10="",COUNTIFS(Scores!$A$5:$A$256,Companies!$B$10,Scores!$B$5:$B$256,"collaboration",Scores!$D$5:$D$256,"A")=0),"",SUMIFS(Scores!$E$5:$E$256,Scores!$A$5:$A$256,Companies!$B$10,Scores!$B$5:$B$256,"collaboration",Scores!$D$5:$D$256,"A")) | D40: =IF(OR(Companies!$B$10="",COUNTIFS(Scores!$A$5:$A$256,Companies!$B$10,Scores!$B$5:$B$256,"collaboration",Scores!$D$5:$D$256,"B")=0),"",SUMIFS(Scores!$E$5:$E$256,Scores!$A$5:$A$256,Companies!$B$10,Scores!$B$5:$B$256,"collaboration",Scores!$D$5:$D$256,"B")) | E40: =IF(OR(C40="",D40=""),"",ABS(C40-D40)) | F40: =IF(E40="","",IF(E40>0.15,"REVIEW",""))
A41: =IF(Companies!$B$10="","",Companies!$B$10) | B41: feedback | C41: =IF(OR(Companies!$B$10="",COUNTIFS(Scores!$A$5:$A$256,Companies!$B$10,Scores!$B$5:$B$256,"feedback",Scores!$D$5:$D$256,"A")=0),"",SUMIFS(Scores!$E$5:$E$256,Scores!$A$5:$A$256,Companies!$B$10,Scores!$B$5:$B$256,"feedback",Scores!$D$5:$D$256,"A")) | D41: =IF(OR(Companies!$B$10="",COUNTIFS(Scores!$A$5:$A$256,Companies!$B$10,Scores!$B$5:$B$256,"feedback",Scores!$D$5:$D$256,"B")=0),"",SUMIFS(Scores!$E$5:$E$256,Scores!$A$5:$A$256,Companies!$B$10,Scores!$B$5:$B$256,"feedback",Scores!$D$5:$D$256,"B")) | E41: =IF(OR(C41="",D41=""),"",ABS(C41-D41)) | F41: =IF(E41="","",IF(E41>0.15,"REVIEW",""))
A42: =IF(Companies!$B$10="","",Companies!$B$10) | B42: innovation | C42: =IF(OR(Companies!$B$10="",COUNTIFS(Scores!$A$5:$A$256,Companies!$B$10,Scores!$B$5:$B$256,"innovation",Scores!$D$5:$D$256,"A")=0),"",SUMIFS(Scores!$E$5:$E$256,Scores!$A$5:$A$256,Companies!$B$10,Scores!$B$5:$B$256,"innovation",Scores!$D$5:$D$256,"A")) | D42: =IF(OR(Companies!$B$10="",COUNTIFS(Scores!$A$5:$A$256,Companies!$B$10,Scores!$B$5:$B$256,"innovation",Scores!$D$5:$D$256,"B")=0),"",SUMIFS(Scores!$E$5:$E$256,Scores!$A$5:$A$256,Companies!$B$10,Scores!$B$5:$B$256,"innovation",Scores!$D$5:$D$256,"B")) | E42: =IF(OR(C42="",D42=""),"",ABS(C42-D42)) | F42: =IF(E42="","",IF(E42>0.15,"REVIEW",""))
...
